Workbook

Sheet Portfolio Overview
B1: Portfolio Summary
B2: Performance
B3: Period Returns | C3: ='25''_Feb_May'!AB84 -> 0.3597174 | F3: Annual Return | G3: =(1+C3)^(252/80)-1 -> 1.632469
B4: Period Volatility | C4: ='25''_Feb_May'!AB85 -> 0.30530643 | F4: Annual Volatility | G4: =C4*SQRT(252/80) -> 0.54186516
B5: Risk Free Rate | C5: ='25''_Feb_May'!AB86 -> 0.04 | F5: Sharpe Ratio | G5: =(G3-C5)/G4 -> 2.9388658
B9: Company | C9: Ticker | D9: Sector | E9: Weight
B10: BAE Systems | C10: BA | D10: Industrials | E10: ='25''_Feb_May'!V2 -> 0.3
B11: HSBC | C11: HSBA | D11: Financials | E11: ='25''_Feb_May'!V3 -> 0.15
B12: Banco Santander | C12: BNC | D12: Financials | E12: ='25''_Feb_May'!V4 -> 0.1
B13: Kainos Group PLC | C13: KNOS | D13: Tech | E13: ='25''_Feb_May'!V5 -> 0.02
B14: Rolls-Royce | C14: RR | D14: Industrials | E14: ='25''_Feb_May'!V6 -> 0.3
B15: J D Wetherspoon | C15: JDW | D15: Consumer | E15: ='25''_Feb_May'!V7 -> 0.05
B16: Shell PLC | C16: SHEL | D16: Energy | E16: ='25''_Feb_May'!V8 -> 0.03
B17: AstraZeneca PLC | C17: AZN | D17: Healthcare | E17: ='25''_Feb_May'!V9 -> 0.05
B21: Sector
B22: Tech | C22: =SUMIF($D$10:$D$17,B22,$E$10:$E$17) -> 0.02
B23: Financials | C23: =SUMIF($D$10:$D$17,B23,$E$10:$E$17) -> 0.25
B24: Industrials | C24: =SUMIF($D$10:$D$17,B24,$E$10:$E$17) -> 0.6
B25: Consumer | C25: =SUMIF($D$10:$D$17,B25,$E$10:$E$17) -> 0.05
B26: Energy | C26: =SUMIF($D$10:$D$17,B26,$E$10:$E$17) -> 0.03
B27: Healthcare | C27: =SUMIF($D$10:$D$17,B27,$E$10:$E$17) -> 0.05
B28: Total | C28: =SUM(C22:C27) -> 1

Sheet 25'_Feb_May
A1: Date | B1: BA.L | C1: HSBA.L | D1: BNC.L | E1: KNOS.L | F1: RR.L | G1: JDW.L | H1: SHEL.L | I1: AZN.L | K1: Daily Return | L1: BA.L | M1: HSBA.L | N1: BNC.L | O1: KNOS.L | P1: RR.L | Q1: JDW.L | R1: SHEL.L | S1: AZN.L | U1: Portfolio Weight | V1: OUR | X1: Portfolio Daily Return | Y1: OUR | AA1: Portfolio Value | AB1: OUR
A2: 45691 | B2: 1230.8544 | C2: 821.5282 | D2: 400.41931 | E2: 801 | F2: 595.35071 | G2: 611.46259 | H2: 2626.7241 | I2: 11274.382 | K2: 45691 | U2: BA | V2: ='Portfolio Analysis'!P3 -> 0.3 | X2: 45691 | AA2: 45691 | AB2: 100
A3: 45692 | B3: 1210.3568 | C3: 829.12756 | D3: 421.41507 | E3: 796 | F3: 593.55078 | G3: 606.46289 | H3: 2651.7214 | I3: 11028.417 | K3: 45692 | L3: =B3/B2-1 -> -0.016653114 | M3: =C3/C2-1 -> 0.0092502792 | N3: =D3/D2-1 -> 0.052434429 | O3: =E3/E2-1 -> -0.0062421973 | P3: =F3/F2-1 -> -0.003023305 | Q3: =G3/G2-1 -> -0.0081766161 | R3: =H3/H2-1 -> 0.0095165359 | S3: =I3/I2-1 -> -0.02181626 | U3: HSBA | V3: ='Portfolio Analysis'!P4 -> 0.15 | X3: 45692 | Y3: {=MMULT(L3:S3,$V$2:$V$9)} -> -0.00061093266 | AA3: 45692 | AB3: =(1+Y3)*AB2 -> 99.938907
A4: 45693 | B4: 1207.8572 | C4: 826.4278 | D4: 457.40784 | E4: 799 | F4: 601.75012 | G4: 610.96259 | H4: 2644.7222 | I4: 11124.403 | K4: 45693 | L4: =B4/B3-1 -> -0.002065204 | M4: =C4/C3-1 -> -0.0032561552 | N4: =D4/D3-1 -> 0.085409303 | O4: =E4/E3-1 -> 0.0037688442 | P4: =F4/F3-1 -> 0.013814051 | Q4: =G4/G3-1 -> 0.0074195716 | R4: =H4/H3-1 -> -0.0026395184 | S4: =I4/I3-1 -> 0.0087035454 | U4: BNC | V4: ='Portfolio Analysis'!P5 -> 0.1 | X4: 45693 | Y4: {=MMULT(L4:S4,$V$2:$V$9)} -> 0.012379508 | AA4: 45693 | AB4: =(1+Y4)*AB3 -> 101.1761
A5: 45694 | B5: 1184.8599 | C5: 847.9259 | D5: 465.40622 | E5: 810 | F5: 605.94977 | G5: 614.4624 | H5: 2646.2222 | I5: 11784.309 | K5: 45694 | L5: =B5/B4-1 -> -0.019039763 | M5: =C5/C4-1 -> 0.026013292 | N5: =D5/D4-1 -> 0.017486326 | O5: =E5/E4-1 -> 0.013767209 | P5: =F5/F4-1 -> 0.006979053 | Q5: =G5/G4-1 -> 0.0057283653 | R5: =H5/H4-1 -> 0.00056716733 | S5: =I5/I4-1 -> 0.05932051 | U5: KNOS | V5: ='Portfolio Analysis'!P6 -> 0.02 | X5: 45694 | Y5: {=MMULT(L5:S5,$V$2:$V$9)} -> 0.0055772164 | AA5: 45694 | AB5: =(1+Y5)*AB4 -> 101.74038
A6: 45695 | B6: 1196.8584 | C6: 853.92535 | D6: 464.90631 | E6: 781 | F6: 602.75006 | G6: 605.96289 | H6: 2644.7222 | I6: 11598.335 | K6: 45695 | L6: =B6/B5-1 -> 0.010126544 | M6: =C6/C5-1 -> 0.0070754422 | N6: =D6/D5-1 -> -0.0010741336 | O6: =E6/E5-1 -> -0.035802469 | P6: =F6/F5-1 -> -0.0052804823 | Q6: =G6/G5-1 -> -0.013832436 | R6: =H6/H5-1 -> -0.00056684583 | S6: =I6/I5-1 -> -0.015781463 | U6: RR | V6: ='Portfolio Analysis'!P7 -> 0.3 | X6: 45695 | Y6: {=MMULT(L6:S6,$V$2:$V$9)} -> 0.00019397167 | AA6: 45695 | AB6: =(1+Y6)*AB5 -> 101.76012
A7: 45698 | B7: 1180.3604 | C7: 866.12433 | D7: 454.40845 | E7: 790 | F7: 613.34918 | G7: 613.9624 | H7: 2639.2229 | I7: 11716.318 | K7: 45698 | L7: =B7/B6-1 -> -0.01378446 | M7: =C7/C6-1 -> 0.014285762 | N7: =D7/D6-1 -> -0.022580601 | O7: =E7/E6-1 -> 0.011523688 | P7: =F7/F6-1 -> 0.017584604 | Q7: =G7/G6-1 -> 0.013201323 | R7: =H7/H6-1 -> -0.0020793366 | S7: =I7/I6-1 -> 0.010172443 | U7: JDW | V7: ='Portfolio Analysis'!P8 -> 0.05 | X7: 45698 | Y7: {=MMULT(L7:S7,$V$2:$V$9)} -> 0.0023616293 | AA7: 45698 | AB7: =(1+Y7)*AB6 -> 102.00044
A8: 45699 | B8: 1204.8575 | C8: 875.52344 | D8: 467.40582 | E8: 786 | F8: 619.94861 | G8: 597.96338 | H8: 2699.2166 | I8: 11622.332 | K8: 45699 | L8: =B8/B7-1 -> 0.020753995 | M8: =C8/C7-1 -> 0.010851916 | N8: =D8/D7-1 -> 0.028602847 | O8: =E8/E7-1 -> -0.0050632911 | P8: =F8/F7-1 -> 0.010759656 | Q8: =G8/G7-1 -> -0.026058637 | R8: =H8/H7-1 -> 0.022731559 | S8: =I8/I7-1 -> -0.0080218312 | U8: SHEL | V8: ='Portfolio Analysis'!P9 -> 0.03 | X8: 45699 | Y8: {=MMULT(L8:S8,$V$2:$V$9)} -> 0.012818825 | AA8: 45699 | AB8: =(1+Y8)*AB7 -> 103.30796
A9: 45700 | B9: 1209.3569 | C9: 881.62299 | D9: 477.40381 | E9: 778 | F9: 620.74854 | G9: 600.46326 | H9: 2701.2163 | I9: 11800.306 | K9: 45700 | L9: =B9/B8-1 -> 0.0037343748 | M9: =C9/C8-1 -> 0.0069667448 | N9: =D9/D8-1 -> 0.021390375 | O9: =E9/E8-1 -> -0.010178117 | P9: =F9/F8-1 -> 0.0012903114 | Q9: =G9/G8-1 -> 0.0041806539 | R9: =H9/H8-1 -> 0.00074086529 | S9: =I9/I8-1 -> 0.015313074 | U9: AZN | V9: ='Portfolio Analysis'!P10 -> 0.05 | X9: 45700 | Y9: {=MMULT(L9:S9,$V$2:$V$9)} -> 0.0054848051 | AA9: 45700 | AB9: =(1+Y9)*AB8 -> 103.87459
A10: 45701 | B10: 1247.8524 | C10: 875.82349 | D10: 472.90469 | E10: 788 | F10: 624.34827 | G10: 603.46307 | H10: 2651.2214 | I10: 11962.283 | K10: 45701 | L10: =B10/B9-1 -> 0.031831366 | M10: =C10/C9-1 -> -0.0065782082 | N10: =D10/D9-1 -> -0.0094241288 | O10: =E10/E9-1 -> 0.01285347 | P10: =F10/F9-1 -> 0.0057990172 | Q10: =G10/G9-1 -> 0.0049958376 | R10: =H10/H9-1 -> -0.018508282 | S10: =I10/I9-1 -> 0.013726555 | V10: =SUM(V2:V9) -> 1 | X10: 45701 | Y10: {=MMULT(L10:S10,$V$2:$V$9)} -> 0.0099979115 | AA10: 45701 | AB10: =(1+Y10)*AB9 -> 104.91312
A11: 45702 | B11: 1227.8547 | C11: 869.62402 | D11: 478.40359 | E11: 794 | F11: 624.54822 | G11: 601.4632 | H11: 2673.7192 | I11: 11706.319 | K11: 45702 | L11: =B11/B10-1 -> -0.016025678 | M11: =C11/C10-1 -> -0.0070784387 | N11: =D11/D10-1 -> 0.011627927 | O11: =E11/E10-1 -> 0.0076142132 | P11: =F11/F10-1 -> 0.00032025583 | Q11: =G11/G10-1 -> -0.0033140022 | R11: =H11/H10-1 -> 0.0084858256 | S11: =I11/I10-1 -> -0.021397576 | X11: 45702 | Y11: {=MMULT(L11:S11,$V$2:$V$9)} -> -0.0054393195 | AA11: 45702 | AB11: =(1+Y11)*AB10 -> 104.34246
A12: 45705 | B12: 1337.8418 | C12: 881.22296 | D12: 483.40259 | E12: 798 | F12: 635.34735 | G12: 600.46326 | H12: 2686.7178 | I12: 11712.318 | K12: 45705 | L12: =B12/B11-1 -> 0.089576606 | M12: =C12/C11-1 -> 0.013337877 | N12: =D12/D11-1 -> 0.010449321 | O12: =E12/E11-1 -> 0.0050377834 | P12: =F12/F11-1 -> 0.017291112 | Q12: =G12/G11-1 -> -0.0016625106 | R12: =H12/H11-1 -> 0.0048615932 | S12: =I12/I11-1 -> 0.00051246026 | X12: 45705 | Y12: {=MMULT(L12:S12,$V$2:$V$9)} -> 0.03529503 | AA12: 45705 | AB12: =(1+Y12)*AB11 -> 108.02523
A13: 45706 | B13: 1336.3419 | C13: 898.02148 | D13: 491.40097 | E13: 790 | F13: 644.34662 | G13: 604.46301 | H13: 2679.7185 | I13: 11786.308 | K13: 45706 | L13: =B13/B12-1 -> -0.0011211176 | M13: =C13/C12-1 -> 0.019062739 | N13: =D13/D12-1 -> 0.016546007 | O13: =E13/E12-1 -> -0.010025063 | P13: =F13/F12-1 -> 0.014164327 | Q13: =G13/G12-1 -> 0.0066611168 | R13: =H13/H12-1 -> -0.0026051369 | S13: =I13/I12-1 -> 0.0063172171 | X13: 45706 | Y13: {=MMULT(L13:S13,$V$2:$V$9)} -> 0.0087972356 | AA13: 45706 | AB13: =(1+Y13)*AB12 -> 108.97555
A14: 45707 | B14: 1344.8409 | C14: 895.32178 | D14: 477.90369 | E14: 791 | F14: 642.54675 | G14: 587.46405 | H14: 2685.718 | I14: 11702.32 | K14: 45707 | L14: =B14/B13-1 -> 0.0063599168 | M14: =C14/C13-1 -> -0.0030062833 | N14: =D14/D13-1 -> -0.027466946 | O14: =E14/E13-1 -> 0.0012658228 | P14: =F14/F13-1 -> -0.0027933191 | Q14: =G14/G13-1 -> -0.028122419 | R14: =H14/H13-1 -> 0.0022388589 | S14: =I14/I13-1 -> -0.0071258368 | X14: 45707 | Y14: {=MMULT(L14:S14,$V$2:$V$9)} -> -0.0037975884 | AA14: 45707 | AB14: =(1+Y14)*AB13 -> 108.56171
A15: 45708 | B15: 1283.8481 | C15: 879.72308 | D15: 482.4028 | E15: 753 | F15: 618.34882 | G15: 592.46375 | H15: 2683.718 | I15: 11590 | K15: 45708 | L15: =B15/B14-1 -> -0.045353168 | M15: =C15/C14-1 -> -0.017422444 | N15: =D15/D14-1 -> 0.0094142714 | O15: =E15/E14-1 -> -0.048040455 | P15: =F15/F14-1 -> -0.037659418 | Q15: =G15/G14-1 -> 0.0085106396 | R15: =H15/H14-1 -> -0.00074467982 | S15: =I15/I14-1 -> -0.0095981232 | X15: 45708 | Y15: {=MMULT(L15:S15,$V$2:$V$9)} -> -0.027613239 | AA15: 45708 | AB15: =(1+Y15)*AB14 -> 105.56397
A16: 45709 | B16: 1255.3516 | C16: 885.7226 | D16: 484.4024 | E16: 749 | F16: 611.34937 | G16: 603.96301 | H16: 2637.2229 | I16: 11708 | K16: 45709 | L16: =B16/B15-1 -> -0.022196225 | M16: =C16/C15-1 -> 0.006819773 | N16: =D16/D15-1 -> 0.0041450905 | O16: =E16/E15-1 -> -0.005312085 | P16: =F16/F15-1 -> -0.011319583 | Q16: =G16/G15-1 -> 0.019409234 | R16: =H16/H15-1 -> -0.017324889 | S16: =I16/I15-1 -> 0.010181191 | X16: 45709 | Y16: {=MMULT(L16:S16,$V$2:$V$9)} -> -0.0077637344 | AA16: 45709 | AB16: =(1+Y16)*AB15 -> 104.7444
A17: 45712 | B17: 1304.8457 | C17: 877.62329 | D17: 492.40079 | E17: 762 | F17: 606.14978 | G17: 598.96332 | H17: 2633.2234 | I17: 11772 | K17: 45712 | L17: =B17/B16-1 -> 0.039426518 | M17: =C17/C16-1 -> -0.0091442899 | N17: =D17/D16-1 -> 0.016511856 | O17: =E17/E16-1 -> 0.017356475 | P17: =F17/F16-1 -> -0.0085050959 | Q17: =G17/G16-1 -> -0.0082781474 | R17: =H17/H16-1 -> -0.0015165619 | S17: =I17/I16-1 -> 0.0054663478 | X17: 45712 | Y17: {=MMULT(L17:S17,$V$2:$V$9)} -> 0.0097170113 | AA17: 45712 | AB17: =(1+Y17)*AB16 -> 105.7622
A18: 45713 | B18: 1365.8385 | C18: 899.42139 | D18: 499.89926 | E18: 765 | F18: 614.94904 | G18: 593.46368 | H18: 2629.2239 | I18: 11932 | K18: 45713 | L18: =B18/B17-1 -> 0.046743303 | M18: =C18/C17-1 -> 0.024837645 | N18: =D18/D17-1 -> 0.015228396 | O18: =E18/E17-1 -> 0.0039370079 | P18: =F18/F17-1 -> 0.014516635 | Q18: =G18/G17-1 -> -0.0091819209 | R18: =H18/H17-1 -> -0.0015188653 | S18: =I18/I17-1 -> 0.013591573 | X18: 45713 | Y18: {=MMULT(L18:S18,$V$2:$V$9)} -> 0.023880125 | AA18: 45713 | AB18: =(1+Y18)*AB17 -> 108.28781
A19: 45714 | B19: 1344.8409 | C19: 911.62036 | D19: 512.89667 | E19: 749 | F19: 630.94769 | G19: 599.96326 | H19: 2646.7219 | I19: 11882 | K19: 45714 | L19: =B19/B18-1 -> -0.015373383 | M19: =C19/C18-1 -> 0.013563136 | N19: =D19/D18-1 -> 0.02600005 | O19: =E19/E18-1 -> -0.020915033 | P19: =F19/F18-1 -> 0.026016233 | Q19: =G19/G18-1 -> 0.01095193 | R19: =H19/H18-1 -> 0.0066552137 | S19: =I19/I18-1 -> -0.0041904123 | X19: 45714 | Y19: {=MMULT(L19:S19,$V$2:$V$9)} -> 0.007946762 | AA19: 45714 | AB19: =(1+Y19)*AB18 -> 109.14835
A20: 45715 | B20: 1391.3354 | C20: 912.22028 | D20: 509.89725 | E20: 716 | F20: 731.53937 | G20: 594.96356 | H20: 2651.7214 | I20: 12018 | K20: 45715 | L20: =B20/B19-1 -> 0.034572495 | M20: =C20/C19-1 -> 0.00065807498 | N20: =D20/D19-1 -> -0.0058480009 | O20: =E20/E19-1 -> -0.044058745 | P20: =F20/F19-1 -> 0.1594295 | Q20: =G20/G19-1 -> -0.008333335 | R20: =H20/H19-1 -> 0.0018889448 | S20: =I20/I19-1 -> 0.011445885 | X20: 45715 | Y20: {=MMULT(L20:S20,$V$2:$V$9)} -> 0.05704563 | AA20: 45715 | AB20: =(1+Y20)*AB19 -> 115.37479
A21: 45716 | B21: 1406.3336 | C21: 933.51837 | D21: 509.89725 | E21: 697 | F21: 743.93835 | G21: 593.96362 | H21: 2635.7231 | I21: 11968 | K21: 45716 | L21: =B21/B20-1 -> 0.010779693 | M21: =C21/C20-1 -> 0.023347536 | N21: =D21/D20-1 -> 0 | O21: =E21/E20-1 -> -0.026536313 | P21: =F21/F20-1 -> 0.016949172 | Q21: =G21/G20-1 -> -0.0016806726 | R21: =H21/H20-1 -> -0.0060331718 | S21: =I21/I20-1 -> -0.004160426 | X21: 45716 | Y21: {=MMULT(L21:S21,$V$2:$V$9)} -> 0.010817014 | AA21: 45716 | AB21: =(1+Y21)*AB20 -> 116.6228
A22: 45719 | B22: 1611.3094 | C22: 942.41766 | D22: 516.89581 | E22: 699 | F22: 776.73566 | G22: 594.46362 | H22: 2656.2209 | I22: 11904 | K22: 45719 | L22: =B22/B21-1 -> 0.14575192 | M22: =C22/C21-1 -> 0.0095330657 | N22: =D22/D21-1 -> 0.013725443 | O22: =E22/E21-1 -> 0.0028694405 | P22: =F22/F21-1 -> 0.044086048 | Q22: =G22/G21-1 -> 0.00084180239 | R22: =H22/H21-1 -> 0.007776918 | S22: =I22/I21-1 -> -0.0053475936 | X22: 45719 | Y22: {=MMULT(L22:S22,$V$2:$V$9)} -> 0.059819303 | AA22: 45719 | AB22: =(1+Y22)*AB21 -> 123.59909
... A81: 45807 | B81: 1901.5 | C81: 873.20001 | D81: 592 | E81: 727 | F81: 866.20001 | G81: 731.5 | H81: 2449.5 | I81: 10720 | K81: 45807 | L81: =B81/B80-1 -> 0.010092961 | M81: =C81/C80-1 -> 0.0020656274 | N81: =D81/D80-1 -> 0.0033898305 | O81: =E81/E80-1 -> 0.012534819 | P81: =F81/F80-1 -> 0.017861354 | Q81: =G81/G80-1 -> 0.0027416038 | R81: =H81/H80-1 -> 0.0032766742 | S81: =I81/I80-1 -> 0.030967494 | X81: 45807 | Y81: {=MMULT(L81:S81,$V$2:$V$9)} -> 0.011069573 | AA81: 45807 | AB81: =(1+Y81)*AB80 -> 135.97174
AB83: Our
AA84: Period Portfolio Returns | AB84: =AB81/AB2-1 -> 0.3597174
AA85: Period Volatility | AB85: =STDEV(Y3:Y81)*SQRT(252) -> 0.30530643
AA86: Rf | AB86: 0.04

Sheet Portfolio Analysis
B1: Security Monthly Returns | L1: Portfolio Weights | S1: Portfolio Monthly Returns | Z1: Portfolio Value
B2: BA | C2: HSBA | D2: BNC | E2: KNOS | F2: RR | G2: JDW | H2: SHEL | I2: AZN | K2: Company | L2: EW | M2: MV | N2: RP | O2: ShRa | P2: OUR | S2: EW | T2: MV | U2: RP | V2: ShRa | W2: OUR | Y2: Date | Z2: EW | AA2: MV | AB2: RP | AC2: ShRa | AD2: OUR
A3: Jan | B3: 0.00093450456 | C3: 0.15648643 | D3: 0.13682102 | E3: -0.045366225 | F3: 0.13454938 | G3: 0.022512367 | H3: 0.020636343 | I3: -0.055981389 | K3: BA | L3: =Calculation!N5 -> 0.125 | M3: =Calculation!U5 -> 0.45354554 | N3: =Calculation!AB5 -> 0.17162466 | O3: 0 | P3: 0.3 | R3: 44957 | S3: {=MMULT($B3:$I3,L$3:L$10)} -> 0.046324054 | T3: {=MMULT($B3:$I3,M$3:M$10)} -> 0.058545611 | U3: {=MMULT($B3:$I3,N$3:N$10)} -> 0.042325858 | V3: {=MMULT($B3:$I3,O$3:O$10)} -> 0.13454938 | W3: {=MMULT($B3:$I3,P$3:P$10)} -> 0.075838547 | Y3: 44926 | Z3: 100 | AA3: 100 | AB3: 100 | AC3: 100 | AD3: 100
A4: Feb | B4: 0.048085901 | C4: 0.065727452 | D4: 0.15274326 | E4: -0.055668651 | F4: 0.37072066 | G4: 0.23844118 | H4: 0.064337029 | I4: 0.027529803 | K4: HSBA | L4: =Calculation!N6 -> 0.125 | M4: =Calculation!U6 -> 0.39276681 | N4: =Calculation!AB6 -> 0.16986704 | O4: 0 | P4: 0.15 | R4: 44985 | S4: {=MMULT($B4:$I4,L$3:L$10)} -> 0.11398958 | T4: {=MMULT($B4:$I4,M$3:M$10)} -> 0.064596886 | U4: {=MMULT($B4:$I4,N$3:N$10)} -> 0.091041706 | V4: {=MMULT($B4:$I4,O$3:O$10)} -> 0.37072066 | W4: {=MMULT($B4:$I4,P$3:P$10)} -> 0.1648907 | Y4: 44957 | Z4: =(1+S3)*Z3 -> 104.63241 | AA4: =(1+T3)*AA3 -> 105.85456 | AB4: =(1+U3)*AB3 -> 104.23259 | AC4: =(1+V3)*AC3 -> 113.45494 | AD4: =(1+W3)*AD3 -> 107.58385
A5: Mar | B5: 0.094209396 | C5: -0.1348973 | D5: -0.077844344 | E5: -0.006470251 | F5: 0.028149607 | G5: 0.27111111 | H5: -0.086285429 | I5: 0.0323529 | K5: BNC | L5: =Calculation!N7 -> 0.125 | M5: =Calculation!U7 -> 0 | N5: =Calculation!AB7 -> 0.094048457 | O5: 0 | P5: 0.1 | R5: 45016 | S5: {=MMULT($B5:$I5,L$3:L$10)} -> 0.015040712 | T5: {=MMULT($B5:$I5,M$3:M$10)} -> 0.0098343155 | U5: {=MMULT($B5:$I5,N$3:N$10)} -> 0.0039395676 | V5: {=MMULT($B5:$I5,O$3:O$10)} -> 0.028149607 | W5: {=MMULT($B5:$I5,P$3:P$10)} -> 0.021143905 | Y5: 44985 | Z5: =(1+S4)*Z4 -> 116.55941 | AA5: =(1+T4)*AA4 -> 112.69244 | AB5: =(1+U4)*AB4 -> 113.7221 | AC5: =(1+V4)*AC4 -> 155.51503 | AD5: =(1+W4)*AD4 -> 125.32343
A6: Apr | B6: 0.032123935 | C6: 0.043842097 | D6: -0.062410626 | E6: -0.10274951 | F6: 0.021003821 | G6: -0.002797167 | H6: 0.062161696 | I6: 0.045762175 | K6: KNOS | L6: =Calculation!N8 -> 0.125 | M6: =Calculation!U8 -> 0.012528611 | N6: =Calculation!AB8 -> 0.11307858 | O6: 0 | P6: 0.02 | R6: 45044 | S6: {=MMULT($B6:$I6,L$3:L$10)} -> 0.0046170521 | T6: {=MMULT($B6:$I6,M$3:M$10)} -> 0.033788358 | U6: {=MMULT($B6:$I6,N$3:N$10)} -> 0.012183741 | V6: {=MMULT($B6:$I6,O$3:O$10)} -> 0.021003821 | W6: {=MMULT($B6:$I6,P$3:P$10)} -> 0.01823169 | Y6: 45016 | Z6: =(1+S5)*Z5 -> 118.31255 | AA6: =(1+T5)*AA5 -> 113.80069 | AB6: =(1+U5)*AB5 -> 114.17011 | AC6: =(1+V5)*AC5 -> 159.89271 | AD6: =(1+W5)*AD5 -> 127.97326
A7: May | B7: -0.084615349 | C7: 0.029240147 | D7: -0.071048005 | E7: 0.033870889 | F7: -0.05816623 | G7: 0.028751726 | H7: -0.094325976 | I7: -0.0073216636 | K7: RR | L7: =Calculation!N9 -> 0.125 | M7: =Calculation!U9 -> 0 | N7: =Calculation!AB9 -> 0.076722924 | O7: 1 | P7: 0.3 | R7: 45077 | S7: {=MMULT($B7:$I7,L$3:L$10)} -> -0.027951808 | T7: {=MMULT($B7:$I7,M$3:M$10)} -> -0.025144039 | U7: {=MMULT($B7:$I7,N$3:N$10)} -> -0.029114952 | V7: {=MMULT($B7:$I7,O$3:O$10)} -> -0.05816623 | W7: {=MMULT($B7:$I7,P$3:P$10)} -> -0.046634111 | Y7: 45044 | Z7: =(1+S6)*Z6 -> 118.8588 | AA7: =(1+T6)*AA6 -> 117.64583 | AB7: =(1+U6)*AB6 -> 115.56113 | AC7: =(1+V6)*AC6 -> 163.25107 | AD7: =(1+W6)*AD6 -> 130.30643
A8: Jun | B8: -0.0012928399 | C8: 0.052836692 | D8: 0.13575531 | E8: -0.039001527 | F8: 0.054082352 | G8: -0.08316285 | H8: 0.054942618 | I8: -0.032933139 | K8: JDW | L8: =Calculation!N10 -> 0.125 | M8: =Calculation!U10 -> 0.065352325 | N8: =Calculation!AB10 -> 0.091862709 | O8: 0 | P8: 0.05 | R8: 45107 | S8: {=MMULT($B8:$I8,L$3:L$10)} -> 0.017653327 | T8: {=MMULT($B8:$I8,M$3:M$10)} -> 0.011746064 | U8: {=MMULT($B8:$I8,N$3:N$10)} -> 0.017251398 | V8: {=MMULT($B8:$I8,O$3:O$10)} -> 0.054082352 | W8: {=MMULT($B8:$I8,P$3:P$10)} -> 0.032401337 | Y8: 45077 | Z8: =(1+S7)*Z7 -> 115.53648 | AA8: =(1+T7)*AA7 -> 114.68774 | AB8: =(1+U7)*AB7 -> 112.19658 | AC8: =(1+V7)*AC7 -> 153.75537 | AD8: =(1+W7)*AD7 -> 124.2297
A9: Jul | B9: 0.0047465275 | C9: 0.039568889 | D9: 0.060606061 | E9: 0.0633117 | F9: 0.22376693 | G9: 0.0052043939 | H9: 0.010031957 | I9: -0.0079815542 | K9: SHEL | L9: =Calculation!N11 -> 0.125 | M9: =Calculation!U11 -> 0 | N9: =Calculation!AB11 -> 0.14730211 | O9: 0 | P9: 0.03 | R9: 45138 | S9: {=MMULT($B9:$I9,L$3:L$10)} -> 0.049906863 | T9: {=MMULT($B9:$I9,M$3:M$10)} -> 0.018222384 | U9: {=MMULT($B9:$I9,N$3:N$10)} -> 0.038437597 | V9: {=MMULT($B9:$I9,O$3:O$10)} -> 0.22376693 | W9: {=MMULT($B9:$I9,P$3:P$10)} -> 0.081978311 | Y9: 45107 | Z9: =(1+S8)*Z8 -> 117.57609 | AA9: =(1+T8)*AA8 -> 116.03487 | AB9: =(1+U8)*AB8 -> 114.13212 | AC9: =(1+V8)*AC8 -> 162.07083 | AD9: =(1+W8)*AD8 -> 128.25491
A10: Aug | B10: 0.08170497 | C10: -0.097674277 | D10: -0.026984165 | E10: -0.072519038 | F10: 0.20259671 | G10: 0.069526639 | H10: 0.019340434 | I10: -0.046783141 | K10: AZN | L10: =Calculation!N12 -> 0.125 | M10: =Calculation!U12 -> 0.075806704 | N10: =Calculation!AB12 -> 0.13549352 | O10: 0 | P10: 0.05 | R10: 45169 | S10: {=MMULT($B10:$I10,L$3:L$10)} -> 0.016151017 | T10: {=MMULT($B10:$I10,M$3:M$10)} -> -0.0012176004 | U10: {=MMULT($B10:$I10,N$3:N$10)} -> 0.00513357 | V10: {=MMULT($B10:$I10,O$3:O$10)} -> 0.20259671 | W10: {=MMULT($B10:$I10,P$3:P$10)} -> 0.068207953 | Y10: 45138 | Z10: =(1+S9)*Z9 -> 123.44394 | AA10: =(1+T9)*AA9 -> 118.1493 | AB10: =(1+U9)*AB9 -> 118.51909 | AC10: =(1+V9)*AC9 -> 198.33692 | AD10: =(1+W9)*AD9 -> 138.76903
A11: Sep | B11: -0.0096278024 | C11: 0.10598535 | D11: 0.01957589 | E11: -0.054189948 | F11: -0.0062978095 | G11: -0.043568412 | H11: 0.08065529 | I11: 0.041268129 | O11: =SUM(O3:O10) -> 1 | P11: =SUM(P3:P10) -> 1 | R11: 45198 | S11: {=MMULT($B11:$I11,L$3:L$10)} -> 0.016725087 | T11: {=MMULT($B11:$I11,M$3:M$10)} -> 0.036863062 | U11: {=MMULT($B11:$I11,N$3:N$10)} -> 0.025051171 | V11: {=MMULT($B11:$I11,O$3:O$10)} -> -0.0062978095 | W11: {=MMULT($B11:$I11,P$3:P$10)} -> 0.014298554 | Y11: 45169 | Z11: =(1+S10)*Z10 -> 125.43768 | AA11: =(1+T10)*AA10 -> 118.00544 | AB11: =(1+U10)*AB10 -> 119.12751 | AC11: =(1+V10)*AC10 -> 238.51932 | AD11: =(1+W10)*AD10 -> 148.23418
A12: Oct | B12: 0.10655277 | C12: -0.081563132 | D12: -0.036800103 | E12: -0.023498618 | F12: -0.024898204 | G12: -0.086044869 | H12: 0.015541045 | I12: -0.076742952 | R12: 45230 | S12: {=MMULT($B12:$I12,L$3:L$10)} -> -0.025931758 | T12: {=MMULT($B12:$I12,M$3:M$10)} -> 0.0045559749 | U12: {=MMULT($B12:$I12,N$3:N$10)} -> -0.019609511 | V12: {=MMULT($B12:$I12,O$3:O$10)} -> -0.024898204 | W12: {=MMULT($B12:$I12,P$3:P$10)} -> 0.00043875772 | Y12: 45198 | Z12: =(1+S11)*Z11 -> 127.53564 | AA12: =(1+T11)*AA11 -> 122.35548 | AB12: =(1+U11)*AB11 -> 122.1118 | AC12: =(1+V11)*AC11 -> 237.01717 | AD12: =(1+W11)*AD11 -> 150.35372
A13: Nov | B13: -0.048913015 | C13: 0.016678736 | D13: 0.07475089 | E13: -0.13941104 | F13: 0.24791085 | G13: 0.085443003 | H13: -0.032588132 | I13: -0.012097522 | R13: 45260 | S13: {=MMULT($B13:$I13,L$3:L$10)} -> 0.02397172 | T13: {=MMULT($B13:$I13,M$3:M$10)} -> -0.012713227 | U13: {=MMULT($B13:$I13,N$3:N$10)} -> 0.006134326 | V13: {=MMULT($B13:$I13,O$3:O$10)} -> 0.24791085 | W13: {=MMULT($B13:$I13,P$3:P$10)} -> 0.069577658 | Y13: 45230 | Z13: =(1+S12)*Z12 -> 124.22842 | AA13: =(1+T12)*AA12 -> 122.91293 | AB13: =(1+U12)*AB12 -> 119.71725 | AC13: =(1+V12)*AC12 -> 231.11587 | AD13: =(1+W12)*AD12 -> 150.41969
A14: Dec | B14: 0.057618986 | C14: 0.055472625 | D14: 0.017001615 | E14: 0.15898496 | F14: 0.11495544 | G14: 0.18148687 | H14: 0.004492171 | I14: 0.046810122 | R14: 45289 | S14: {=MMULT($B14:$I14,L$3:L$10)} -> 0.079602849 | T14: {=MMULT($B14:$I14,M$3:M$10)} -> 0.065321611 | U14: {=MMULT($B14:$I14,N$3:N$10)} -> 0.071384345 | V14: {=MMULT($B14:$I14,O$3:O$10)} -> 0.11495544 | W14: {=MMULT($B14:$I14,P$3:P$10)} -> 0.076522698 | Y14: 45260 | Z14: =(1+S13)*Z13 -> 127.20639 | AA14: =(1+T13)*AA13 -> 121.35031 | AB14: =(1+U13)*AB13 -> 120.45163 | AC14: =(1+V13)*AC13 -> 288.412 | AD14: =(1+W13)*AD13 -> 160.88554
A15: Jan | B15: 0.059883024 | C15: -0.027246674 | D15: -0.036441931 | E15: 0.025022395 | F15: 0.0050050123 | G15: 0.036397347 | H15: -0.048237315 | I15: -0.0094339414 | R15: 45322 | S15: {=MMULT($B15:$I15,L$3:L$10)} -> 0.00061848962 | T15: {=MMULT($B15:$I15,M$3:M$10)} -> 0.01843508 | U15: {=MMULT($B15:$I15,N$3:N$10)} -> 0.00039514271 | V15: {=MMULT($B15:$I15,O$3:O$10)} -> 0.0050050123 | W15: {=MMULT($B15:$I15,P$3:P$10)} -> 0.012136715 | Y15: 45289 | Z15: =(1+S14)*Z14 -> 137.33238 | AA15: =(1+T14)*AA14 -> 129.27711 | AB15: =(1+U14)*AB14 -> 129.04999 | AC15: =(1+V14)*AC14 -> 321.56653 | AD15: =(1+W14)*AD14 -> 173.19693
A16: Feb | B16: 0.055225194 | C16: -0.0059850562 | D16: 0.033122963 | E16: -0.038360961 | F16: 0.22543162 | G16: -0.097619027 | H16: 0.0041947832 | I16: -0.049091196 | R16: 45351 | S16: {=MMULT($B16:$I16,L$3:L$10)} -> 0.01586479 | T16: {=MMULT($B16:$I16,M$3:M$10)} -> 0.012114727 | U16: {=MMULT($B16:$I16,N$3:N$10)} -> 0.0095332876 | V16: {=MMULT($B16:$I16,O$3:O$10)} -> 0.22543162 | W16: {=MMULT($B16:$I16,P$3:P$10)} -> 0.078634695 | Y16: 45322 | Z16: =(1+S15)*Z15 -> 137.41732 | AA16: =(1+T15)*AA15 -> 131.66034 | AB16: =(1+U15)*AB15 -> 129.10098 | AC16: =(1+V15)*AC15 -> 323.17598 | AD16: =(1+W15)*AD15 -> 175.29897
A17: Mar | B17: 0.086553842 | C17: 0.0073229024 | D17: 0.17862591 | E17: -0.12466008 | F17: 0.15605531 | G17: -0.029683478 | H17: 0.068376096 | I17: 0.069618316 | R17: 45379 | S17: {=MMULT($B17:$I17,L$3:L$10)} -> 0.051526102 | T17: {=MMULT($B17:$I17,M$3:M$10)} -> 0.043908135 | U17: {=MMULT($B17:$I17,N$3:N$10)} -> 0.047552789 | V17: {=MMULT($B17:$I17,O$3:O$10)} -> 0.15605531 | W17: {=MMULT($B17:$I17,P$3:P$10)} -> 0.093298596 | Y17: 45351 | Z17: =(1+S16)*Z16 -> 139.59741 | AA17: =(1+T16)*AA16 -> 133.25537 | AB17: =(1+U16)*AB16 -> 130.33174 | AC17: =(1+V16)*AC16 -> 396.03006 | AD17: =(1+W16)*AD16 -> 189.08356
A18: Apr | B18: -0.012088267 | C18: 0.12374808 | D18: 0.0067079839 | E18: 0.016053839 | F18: -0.031872588 | G18: -0.014955787 | H18: 0.090666607 | I18: 0.12961229 | R18: 45412 | S18: {=MMULT($B18:$I18,L$3:L$10)} -> 0.038484021 | T18: {=MMULT($B18:$I18,M$3:M$10)} -> 0.052170778 | U18: {=MMULT($B18:$I18,N$3:N$10)} -> 0.048490069 | V18: {=MMULT($B18:$I18,O$3:O$10)} -> -0.031872588 | W18: {=MMULT($B18:$I18,P$3:P$10)} -> 0.014818655 | Y18: 45379 | Z18: =(1+S17)*Z17 -> 146.79032 | AA18: =(1+T17)*AA17 -> 139.10636 | AB18: =(1+U17)*AB17 -> 136.52938 | AC18: =(1+V17)*AC17 -> 457.83266 | AD18: =(1+W17)*AD17 -> 206.72479
A19: May | B19: 0.044261104 | C19: 0.0013790894 | D19: 0.055341051 | E19: 0.17431202 | F19: 0.097555074 | G19: 0.057280908 | H19: -0.017988053 | I19: 0.010611906 | R19: 45443 | S19: {=MMULT($B19:$I19,L$3:L$10)} -> 0.052844137 | T19: {=MMULT($B19:$I19,M$3:M$10)} -> 0.027347869 | U19: {=MMULT($B19:$I19,N$3:N$10)} -> 0.04428111 | V19: {=MMULT($B19:$I19,O$3:O$10)} -> 0.097555074 | W19: {=MMULT($B19:$I19,P$3:P$10)} -> 0.054627061 | Y19: 45412 | Z19: =(1+S18)*Z18 -> 152.4394 | AA19: =(1+T18)*AA18 -> 146.36365 | AB19: =(1+U18)*AB18 -> 143.1497 | AC19: =(1+V18)*AC18 -> 443.24034 | AD19: =(1+W18)*AD18 -> 209.78817
A20: Jun | B20: -0.051724223 | C20: -0.017949343 | D20: -0.1146341 | E20: -0.081597306 | F20: 0.0074988994 | G20: -0.044386411 | H20: 0.0080028173 | I20: 0.013617622 | R20: 45471 | S20: {=MMULT($B20:$I20,L$3:L$10)} -> -0.035146505 | T20: {=MMULT($B20:$I20,M$3:M$10)} -> -0.033399946 | U20: {=MMULT($B20:$I20,N$3:N$10)} -> -0.032412408 | V20: {=MMULT($B20:$I20,O$3:O$10)} -> 0.0074988994 | W20: {=MMULT($B20:$I20,P$3:P$10)} -> -0.030353709 | Y20: 45443 | Z20: =(1+S19)*Z19 -> 160.49493 | AA20: =(1+T19)*AA19 -> 150.36639 | AB20: =(1+U19)*AB19 -> 149.48853 | AC20: =(1+V19)*AC19 -> 486.48069 | AD20: =(1+W19)*AD19 -> 221.24828
A21: Jul | B21: -0.017424144 | C21: 0.029390201 | D21: 0.024793338 | E21: 0.037807218 | F21: -0.015761818 | G21: 0.019808739 | H21: 0.0021171128 | I21: 0.00097114978 | R21: 45504 | S21: {=MMULT($B21:$I21,L$3:L$10)} -> 0.010212725 | T21: {=MMULT($B21:$I21,M$3:M$10)} -> 0.0054826916 | U21: {=MMULT($B21:$I21,N$3:N$10)} -> 0.0096628067 | V21: {=MMULT($B21:$I21,O$3:O$10)} -> -0.015761818 | W21: {=MMULT($B21:$I21,P$3:P$10)} -> -0.0012092724 | Y21: 45471 | Z21: =(1+S20)*Z20 -> 154.8541 | AA21: =(1+T20)*AA20 -> 145.34416 | AB21: =(1+U20)*AB20 -> 144.64324 | AC21: =(1+V20)*AC20 -> 490.12876 | AD21: =(1+W20)*AD20 -> 214.53257
A22: Aug | B22: 0.050886619 | C22: -0.052872382 | D22: 0.0040322501 | E22: 0.0072859587 | F22: 0.1040925 | G22: 0.016744839 | H22: -0.055985865 | I22: 0.073319261 | R22: 45534 | S22: {=MMULT($B22:$I22,L$3:L$10)} -> 0.018437898 | T22: {=MMULT($B22:$I22,M$3:M$10)} -> 0.0090565707 | U22: {=MMULT($B22:$I22,N$3:N$10)} -> 0.012167193 | V22: {=MMULT($B22:$I22,O$3:O$10)} -> 0.1040925 | W22: {=MMULT($B22:$I22,P$3:P$10)} -> 0.041935453 | Y22: 45504 | Z22: =(1+S21)*Z21 -> 156.43558 | AA22: =(1+T21)*AA21 -> 146.14103 | AB22: =(1+U21)*AB21 -> 146.0409 | AC22: =(1+V21)*AC21 -> 482.40344 | AD22: =(1+W21)*AD21 -> 214.27315
A23: Sep | B23: -0.092076379 | C23: 0.003749736 | D23: 0.021419076 | E23: -0.20162747 | F23: 0.062046752 | G23: -0.023056759 | H23: -0.095486767 | I23: -0.1270152 | R23: 45565 | S23: {=MMULT($B23:$I23,L$3:L$10)} -> -0.056505876 | T23: {=MMULT($B23:$I23,M$3:M$10)} -> -0.053949588 | U23: {=MMULT($B23:$I23,N$3:N$10)} -> -0.064583724 | V23: {=MMULT($B23:$I23,O$3:O$10)} -> 0.062046752 | W23: {=MMULT($B23:$I23,P$3:P$10)} -> -0.02070527 | Y23: 45534 | Z23: =(1+S22)*Z22 -> 159.31992 | AA23: =(1+T22)*AA22 -> 147.46457 | AB23: =(1+U22)*AB22 -> 147.81781 | AC23: =(1+V22)*AC22 -> 532.61802 | AD23: =(1+W22)*AD22 -> 223.25879
... A26: Dec | B26: -0.066829612 | C26: 0.06687581 | D26: 0 | E26: 0.0025773196 | F26: 0.021124329 | G26: -0.066978206 | H26: -0.035354485 | I26: -0.01922352 | R26: 45656 | S26: {=MMULT($B26:$I26,L$3:L$10)} -> -0.012226046 | T26: {=MMULT($B26:$I26,M$3:M$10)} -> -0.0098458369 | U26: {=MMULT($B26:$I26,N$3:N$10)} -> -0.012162706 | V26: {=MMULT($B26:$I26,O$3:O$10)} -> 0.021124329 | W26: {=MMULT($B26:$I26,P$3:P$10)} -> -0.0089993879 | Y26: 45625 | Z26: =(1+S25)*Z25 -> 146.84289 | AA26: =(1+T25)*AA25 -> 141.83785 | AB26: =(1+U25)*AB25 -> 136.20103 | AC26: =(1+V25)*AC25 -> 599.35623 | AD26: =(1+W25)*AD25 -> 221.50988
Y27: 45656 | Z27: =(1+S26)*Z26 -> 145.04758 | AA27: =(1+T26)*AA26 -> 140.44134 | AB27: =(1+U26)*AB26 -> 134.54446 | AC27: =(1+V26)*AC26 -> 612.01723 | AD27: =(1+W26)*AD26 -> 219.51643
Y34: 2023-2024 Performance | Z34: EW | AA34: MV | AB34: RP | AC34: ShRa | AD34: OUR
Y35: Ann Portfolio Returns | Z35: =(Z27/Z3)^0.5-1 -> 0.204357 | AA35: =(AA27/AA3)^0.5-1 -> 0.18507947 | AB35: =(AB27/AB3)^0.5-1 -> 0.15993301 | AC35: =(AC27/AC3)^0.5-1 -> 1.4738982 | AD35: =(AD27/AD3)^0.5-1 -> 0.48160868
Y36: Ann Volatility | Z36: =STDEV(S3:S26)*SQRT(12) -> 0.13287992 | AA36: =STDEV(T3:T26)*SQRT(12) -> 0.10436389 | AB36: =STDEV(U3:U26)*SQRT(12) -> 0.11998202 | AC36: =STDEV(V3:V26)*SQRT(12) -> 0.37282277 | AD36: =STDEV(W3:W26)*SQRT(12) -> 0.16542535
Y37: Rf | Z37: 0.05 | AA37: 0.05 | AB37: 0.05 | AC37: 0.05 | AD37: 0.05
Y38: Sharpe Ratio | Z38: =(Z35-Z37)/Z36 -> 1.1616278 | AA38: =(AA35-AA37)/AA36 -> 1.2943124 | AB38: =(AB35-AB37)/AB36 -> 0.91624567 | AC38: =(AC35-AC37)/AC36 -> 3.8192361 | AD38: =(AD35-AD37)/AD36 -> 2.6090843

Sheet Calculation
C1: SD Annunalised | D1: =STDEV(D6:D29)*SQRT(12) -> 0.19634389 | E1: =STDEV(E6:E29)*SQRT(12) -> 0.23418518 | F1: =STDEV(F6:F29)*SQRT(12) -> 0.26223325 | G1: =STDEV(G6:G29)*SQRT(12) -> 0.30992316 | H1: =STDEV(H6:H29)*SQRT(12) -> 0.37282277 | I1: =STDEV(I6:I29)*SQRT(12) -> 0.35412736 | J1: =STDEV(J6:J29)*SQRT(12) -> 0.19010922 | K1: =STDEV(K6:K29)*SQRT(12) -> 0.19158111
C2: Total Return | D2: {=PRODUCT(1+D6:D29)-1} -> 0.33829086 | E2: {=PRODUCT(1+E6:E29)-1} -> 0.51748262 | F2: {=PRODUCT(1+F6:F29)-1} -> 0.46748959 | G2: {=PRODUCT(1+G6:G29)-1} -> -0.49550705 | H2: {=PRODUCT(1+H6:H29)-1} -> 5.1201723 | I2: {=PRODUCT(1+I6:I29)-1} -> 0.34872104 | J2: {=PRODUCT(1+J6:J29)-1} -> 0.05059734 | K2: {=PRODUCT(1+K6:K29)-1} -> -0.071814335 | M2: Equally Weighted Asset Allocation | T2: Minimum Variance Portfolio | AA2: Risk Parity | AH2: Maximum Sharpe Ratio
C3: Annualised Total Return | D3: =(1+D2)^0.5-1 -> 0.15684522 | E3: =(1+E2)^0.5-1 -> 0.23186144 | F3: =(1+F2)^0.5-1 -> 0.21139985 | G3: =(1+G2)^0.5-1 -> -0.28972333 | H3: =(1+H2)^0.5-1 -> 1.4738982 | I3: =(1+I2)^0.5-1 -> 0.1613445 | J3: =(1+J2)^0.5-1 -> 0.024986507 | K3: =(1+K2)^0.5-1 -> -0.036576072
M4: Assets | N4: Portfolio's Weights | O4: Annualised Volatility | P4: Marginal Risk Contribution | Q4: Risk Contribution | T4: Assets | U4: Portfolio's Weights | V4: Annualised Volatility | W4: Marginal Risk Contribution | X4: Risk Contribution | AA4: Assets | AB4: Portfolio's Weights | AC4: Annualised Volatility | AD4: Marginal Risk Contribution | AE4: Risk Contribution | AH4: Assets | AI4: Portfolio's Weights | AJ4: Annualised Volatility | AK4: Marginal Risk Contribution | AL4: Risk Contribution
D5: BA | E5: HSBA | F5: BNC | G5: KNOS | H5: RR | I5: JDW | J5: SHEL | K5: AZN | M5: BA | N5: =1/8 -> 0.125 | O5: =B33 -> 0.19634389 | P5: {=MMULT(D44:K51,N5:N12)*N5:N12} -> 0.0014032824 | Q5: =P5/$P$13 -> 0.079474241 | T5: BA | U5: 0.45354554 | V5: =B33 -> 0.19634389 | W5: {=MMULT(D44:K51,U5:U12)*U5:U12} -> 0.0049399374 | X5: =W5/$W$13 -> 0.4535456 | AA5: BA | AB5: 0.17162466 | AC5: =V5 -> 0.19634389 | AD5: {=MMULT(D44:K51,AB5:AB12)*AB5:AB12} -> 0.0017994957 | AE5: =AD5/$AD$13 -> 0.12500243 | AH5: BA | AI5: ='Portfolio Analysis'!O3 -> 0 | AJ5: =AC5 -> 0.19634389 | AK5: {=MMULT(D44:K51,AI5:AI12)*AI5:AI12} -> 0 | AL5: =AK5/$AK$13 -> 0
B6: 2023 | C6: Jan | D6: ='23''24''_Monthly_Return'!L2 -> 0.00093450456 | E6: ='23''24''_Monthly_Return'!M2 -> 0.15648643 | F6: ='23''24''_Monthly_Return'!N2 -> 0.13682102 | G6: ='23''24''_Monthly_Return'!O2 -> -0.045366225 | H6: ='23''24''_Monthly_Return'!P2 -> 0.13454938 | I6: ='23''24''_Monthly_Return'!Q2 -> 0.022512367 | J6: ='23''24''_Monthly_Return'!R2 -> 0.020636343 | K6: ='23''24''_Monthly_Return'!S2 -> -0.055981389 | M6: HSBA | N6: =1/8 -> 0.125 | O6: =B34 -> 0.23418518 | P6: 0.0010929569 | Q6: =P6/$P$13 -> 0.0618991 | T6: HSBA | U6: 0.39276681 | V6: =B34 -> 0.23418518 | W6: 0.0042779448 | X6: =W6/$W$13 -> 0.39276672 | AA6: HSBA | AB6: 0.16986704 | AC6: =V6 -> 0.23418518 | AD6: 0.0017995058 | AE6: =AD6/$AD$13 -> 0.12500313 | AH6: HSBA | AI6: ='Portfolio Analysis'!O4 -> 0 | AJ6: =AC6 -> 0.23418518 | AK6: 0 | AL6: =AK6/$AK$13 -> 0
C7: Feb | D7: ='23''24''_Monthly_Return'!L3 -> 0.048085901 | E7: ='23''24''_Monthly_Return'!M3 -> 0.065727452 | F7: ='23''24''_Monthly_Return'!N3 -> 0.15274326 | G7: ='23''24''_Monthly_Return'!O3 -> -0.055668651 | H7: ='23''24''_Monthly_Return'!P3 -> 0.37072066 | I7: ='23''24''_Monthly_Return'!Q3 -> 0.23844118 | J7: ='23''24''_Monthly_Return'!R3 -> 0.064337029 | K7: ='23''24''_Monthly_Return'!S3 -> 0.027529803 | M7: BNC | N7: =1/8 -> 0.125 | O7: =B35 -> 0.26223325 | P7: 0.0027849416 | Q7: =P7/$P$13 -> 0.15772386 | T7: BNC | U7: 0 | V7: =B35 -> 0.26223325 | W7: 0 | X7: =W7/$W$13 -> 0 | AA7: BNC | AB7: 0.094048457 | AC7: =V7 -> 0.26223325 | AD7: 0.001799484 | AE7: =AD7/$AD$13 -> 0.12500162 | AH7: BNC | AI7: ='Portfolio Analysis'!O5 -> 0 | AJ7: =AC7 -> 0.26223325 | AK7: 0 | AL7: =AK7/$AK$13 -> 0
C8: Mar | D8: ='23''24''_Monthly_Return'!L4 -> 0.094209396 | E8: ='23''24''_Monthly_Return'!M4 -> -0.1348973 | F8: ='23''24''_Monthly_Return'!N4 -> -0.077844344 | G8: ='23''24''_Monthly_Return'!O4 -> -0.006470251 | H8: ='23''24''_Monthly_Return'!P4 -> 0.028149607 | I8: ='23''24''_Monthly_Return'!Q4 -> 0.27111111 | J8: ='23''24''_Monthly_Return'!R4 -> -0.086285429 | K8: ='23''24''_Monthly_Return'!S4 -> 0.0323529 | M8: KNOS | N8: =1/8 -> 0.125 | O8: =B36 -> 0.30992316 | P8: 0.0021004813 | Q8: =P8/$P$13 -> 0.11895977 | T8: KNOS | U8: 0.012528611 | V8: =B36 -> 0.30992316 | W8: 0.00013645944 | X8: =W8/$W$13 -> 0.012528616 | AA8: KNOS | AB8: 0.11307858 | AC8: =V8 -> 0.30992316 | AD8: 0.001799484 | AE8: =AD8/$AD$13 -> 0.12500162 | AH8: KNOS | AI8: ='Portfolio Analysis'!O6 -> 0 | AJ8: =AC8 -> 0.30992316 | AK8: 0 | AL8: =AK8/$AK$13 -> 0
C9: Apr | D9: ='23''24''_Monthly_Return'!L5 -> 0.032123935 | E9: ='23''24''_Monthly_Return'!M5 -> 0.043842097 | F9: ='23''24''_Monthly_Return'!N5 -> -0.062410626 | G9: ='23''24''_Monthly_Return'!O5 -> -0.10274951 | H9: ='23''24''_Monthly_Return'!P5 -> 0.021003821 | I9: ='23''24''_Monthly_Return'!Q5 -> -0.002797167 | J9: ='23''24''_Monthly_Return'!R5 -> 0.062161696 | K9: ='23''24''_Monthly_Return'!S5 -> 0.045762175 | M9: RR | N9: =1/8 -> 0.125 | O9: =B37 -> 0.37282277 | P9: 0.0040561152 | Q9: =P9/$P$13 -> 0.22971618 | T9: RR | U9: 0 | V9: =B37 -> 0.37282277 | W9: 0 | X9: =W9/$W$13 -> 0 | AA9: RR | AB9: 0.076722924 | AC9: =V9 -> 0.37282277 | AD9: 0.0017994815 | AE9: =AD9/$AD$13 -> 0.12500144 | AH9: RR | AI9: ='Portfolio Analysis'!O7 -> 1 | AJ9: =AC9 -> 0.37282277 | AK9: 0.13899682 | AL9: =AK9/$AK$13 -> 1
C10: May | D10: ='23''24''_Monthly_Return'!L6 -> -0.084615349 | E10: ='23''24''_Monthly_Return'!M6 -> 0.029240147 | F10: ='23''24''_Monthly_Return'!N6 -> -0.071048005 | G10: ='23''24''_Monthly_Return'!O6 -> 0.033870889 | H10: ='23''24''_Monthly_Return'!P6 -> -0.05816623 | I10: ='23''24''_Monthly_Return'!Q6 -> 0.028751726 | J10: ='23''24''_Monthly_Return'!R6 -> -0.094325976 | K10: ='23''24''_Monthly_Return'!S6 -> -0.0073216636 | M10: JDW | N10: =1/8 -> 0.125 | O10: =B38 -> 0.35412736 | P10: 0.0033673722 | Q10: =P10/$P$13 -> 0.19070955 | T10: JDW | U10: 0.065352325 | V10: =B38 -> 0.35412736 | W10: 0.00071180618 | X10: =W10/$W$13 -> 0.065352358 | AA10: JDW | AB10: 0.091862709 | AC10: =V10 -> 0.35412736 | AD10: 0.0017994871 | AE10: =AD10/$AD$13 -> 0.12500183 | AH10: JDW | AI10: ='Portfolio Analysis'!O8 -> 0 | AJ10: =AC10 -> 0.35412736 | AK10: 0 | AL10: =AK10/$AK$13 -> 0
C11: Jun | D11: ='23''24''_Monthly_Return'!L7 -> -0.0012928399 | E11: ='23''24''_Monthly_Return'!M7 -> 0.052836692 | F11: ='23''24''_Monthly_Return'!N7 -> 0.13575531 | G11: ='23''24''_Monthly_Return'!O7 -> -0.039001527 | H11: ='23''24''_Monthly_Return'!P7 -> 0.054082352 | I11: ='23''24''_Monthly_Return'!Q7 -> -0.08316285 | J11: ='23''24''_Monthly_Return'!R7 -> 0.054942618 | K11: ='23''24''_Monthly_Return'!S7 -> -0.032933139 | M11: SHEL | N11: =1/8 -> 0.125 | O11: =B39 -> 0.19010922 | P11: 0.001270471 | Q11: =P11/$P$13 -> 0.071952529 | T11: SHEL | U11: 0 | V11: =B39 -> 0.19010922 | W11: 0 | X11: =W11/$W$13 -> 0 | AA11: SHEL | AB11: 0.14730211 | AC11: =V11 -> 0.19010922 | AD11: 0.001799259 | AE11: =AD11/$AD$13 -> 0.12498599 | AH11: SHEL | AI11: ='Portfolio Analysis'!O9 -> 0 | AJ11: =AC11 -> 0.19010922 | AK11: 0 | AL11: =AK11/$AK$13 -> 0
C12: Jul | D12: ='23''24''_Monthly_Return'!L8 -> 0.0047465275 | E12: ='23''24''_Monthly_Return'!M8 -> 0.039568889 | F12: ='23''24''_Monthly_Return'!N8 -> 0.060606061 | G12: ='23''24''_Monthly_Return'!O8 -> 0.0633117 | H12: ='23''24''_Monthly_Return'!P8 -> 0.22376693 | I12: ='23''24''_Monthly_Return'!Q8 -> 0.0052043939 | J12: ='23''24''_Monthly_Return'!R8 -> 0.010031957 | K12: ='23''24''_Monthly_Return'!S8 -> -0.0079815542 | M12: AZN | N12: =1/8 -> 0.125 | O12: =B40 -> 0.19158111 | P12: 0.0015814517 | Q12: =P12/$P$13 -> 0.089564774 | T12: AZN | U12: 0.075806704 | V12: =B40 -> 0.19158111 | W12: 0.00082567307 | X12: =W12/$W$13 -> 0.075806706 | AA12: AZN | AB12: 0.13549352 | AC12: =V12 -> 0.19158111 | AD12: 0.0017994885 | AE12: =AD12/$AD$13 -> 0.12500193 | AH12: AZN | AI12: ='Portfolio Analysis'!O10 -> 0 | AJ12: =AC12 -> 0.19158111 | AK12: 0 | AL12: =AK12/$AK$13 -> 0
C13: Aug | D13: ='23''24''_Monthly_Return'!L9 -> 0.08170497 | E13: ='23''24''_Monthly_Return'!M9 -> -0.097674277 | F13: ='23''24''_Monthly_Return'!N9 -> -0.026984165 | G13: ='23''24''_Monthly_Return'!O9 -> -0.072519038 | H13: ='23''24''_Monthly_Return'!P9 -> 0.20259671 | I13: ='23''24''_Monthly_Return'!Q9 -> 0.069526639 | J13: ='23''24''_Monthly_Return'!R9 -> 0.019340434 | K13: ='23''24''_Monthly_Return'!S9 -> -0.046783141 | M13: Total | N13: =SUM(N5:N12) -> 1 | O13: =SQRT(P13) -> 0.13287992 | P13: =SUM(_xlfn.ANCHORARRAY(P5)) -> 0.017657072 | Q13: =SUM(Q5:Q12) -> 1 | T13: Total | U13: =SUM(U5:U12) -> 1 | V13: =SQRT(W13) -> 0.10436389 | W13: =SUM(W5:W12) -> 0.010891821 | X13: =SUM(X5:X12) -> 1 | AB13: =SUM(AB5:AB12) -> 1 | AC13: =SQRT(AD13) -> 0.11998202 | AD13: =SUM(AD5:AD12) -> 0.014395686 | AE13: =SUM(AE5:AE12) -> 1 | AI13: =SUM(AI5:AI12) -> 1 | AJ13: =SQRT(AK13) -> 0.37282277 | AK13: =SUM(AK5:AK12) -> 0.13899682 | AL13: =SUM(AL5:AL12) -> 1
C14: Sep | D14: ='23''24''_Monthly_Return'!L10 -> -0.0096278024 | E14: ='23''24''_Monthly_Return'!M10 -> 0.10598535 | F14: ='23''24''_Monthly_Return'!N10 -> 0.01957589 | G14: ='23''24''_Monthly_Return'!O10 -> -0.054189948 | H14: ='23''24''_Monthly_Return'!P10 -> -0.0062978095 | I14: ='23''24''_Monthly_Return'!Q10 -> -0.043568412 | J14: ='23''24''_Monthly_Return'!R10 -> 0.08065529 | K14: ='23''24''_Monthly_Return'!S10 -> 0.041268129
C15: Oct | D15: ='23''24''_Monthly_Return'!L11 -> 0.10655277 | E15: ='23''24''_Monthly_Return'!M11 -> -0.081563132 | F15: ='23''24''_Monthly_Return'!N11 -> -0.036800103 | G15: ='23''24''_Monthly_Return'!O11 -> -0.023498618 | H15: ='23''24''_Monthly_Return'!P11 -> -0.024898204 | I15: ='23''24''_Monthly_Return'!Q11 -> -0.086044869 | J15: ='23''24''_Monthly_Return'!R11 -> 0.015541045 | K15: ='23''24''_Monthly_Return'!S11 -> -0.076742952
C16: Nov | D16: ='23''24''_Monthly_Return'!L12 -> -0.048913015 | E16: ='23''24''_Monthly_Return'!M12 -> 0.016678736 | F16: ='23''24''_Monthly_Return'!N12 -> 0.07475089 | G16: ='23''24''_Monthly_Return'!O12 -> -0.13941104 | H16: ='23''24''_Monthly_Return'!P12 -> 0.24791085 | I16: ='23''24''_Monthly_Return'!Q12 -> 0.085443003 | J16: ='23''24''_Monthly_Return'!R12 -> -0.032588132 | K16: ='23''24''_Monthly_Return'!S12 -> -0.012097522
C17: Dec | D17: ='23''24''_Monthly_Return'!L13 -> 0.057618986 | E17: ='23''24''_Monthly_Return'!M13 -> 0.055472625 | F17: ='23''24''_Monthly_Return'!N13 -> 0.017001615 | G17: ='23''24''_Monthly_Return'!O13 -> 0.15898496 | H17: ='23''24''_Monthly_Return'!P13 -> 0.11495544 | I17: ='23''24''_Monthly_Return'!Q13 -> 0.18148687 | J17: ='23''24''_Monthly_Return'!R13 -> 0.004492171 | K17: ='23''24''_Monthly_Return'!S13 -> 0.046810122
B18: 2024 | C18: Jan | D18: ='23''24''_Monthly_Return'!L14 -> 0.059883024 | E18: ='23''24''_Monthly_Return'!M14 -> -0.027246674 | F18: ='23''24''_Monthly_Return'!N14 -> -0.036441931 | G18: ='23''24''_Monthly_Return'!O14 -> 0.025022395 | H18: ='23''24''_Monthly_Return'!P14 -> 0.0050050123 | I18: ='23''24''_Monthly_Return'!Q14 -> 0.036397347 | J18: ='23''24''_Monthly_Return'!R14 -> -0.048237315 | K18: ='23''24''_Monthly_Return'!S14 -> -0.0094339414
C19: Feb | D19: ='23''24''_Monthly_Return'!L15 -> 0.055225194 | E19: ='23''24''_Monthly_Return'!M15 -> -0.0059850562 | F19: ='23''24''_Monthly_Return'!N15 -> 0.033122963 | G19: ='23''24''_Monthly_Return'!O15 -> -0.038360961 | H19: ='23''24''_Monthly_Return'!P15 -> 0.22543162 | I19: ='23''24''_Monthly_Return'!Q15 -> -0.097619027 | J19: ='23''24''_Monthly_Return'!R15 -> 0.0041947832 | K19: ='23''24''_Monthly_Return'!S15 -> -0.049091196
C20: Mar | D20: ='23''24''_Monthly_Return'!L16 -> 0.086553842 | E20: ='23''24''_Monthly_Return'!M16 -> 0.0073229024 | F20: ='23''24''_Monthly_Return'!N16 -> 0.17862591 | G20: ='23''24''_Monthly_Return'!O16 -> -0.12466008 | H20: ='23''24''_Monthly_Return'!P16 -> 0.15605531 | I20: ='23''24''_Monthly_Return'!Q16 -> -0.029683478 | J20: ='23''24''_Monthly_Return'!R16 -> 0.068376096 | K20: ='23''24''_Monthly_Return'!S16 -> 0.069618316
C21: Apr | D21: ='23''24''_Monthly_Return'!L17 -> -0.012088267 | E21: ='23''24''_Monthly_Return'!M17 -> 0.12374808 | F21: ='23''24''_Monthly_Return'!N17 -> 0.0067079839 | G21: ='23''24''_Monthly_Return'!O17 -> 0.016053839 | H21: ='23''24''_Monthly_Return'!P17 -> -0.031872588 | I21: ='23''24''_Monthly_Return'!Q17 -> -0.014955787 | J21: ='23''24''_Monthly_Return'!R17 -> 0.090666607 | K21: ='23''24''_Monthly_Return'!S17 -> 0.12961229
C22: May | D22: ='23''24''_Monthly_Return'!L18 -> 0.044261104 | E22: ='23''24''_Monthly_Return'!M18 -> 0.0013790894 | F22: ='23''24''_Monthly_Return'!N18 -> 0.055341051 | G22: ='23''24''_Monthly_Return'!O18 -> 0.17431202 | H22: ='23''24''_Monthly_Return'!P18 -> 0.097555074 | I22: ='23''24''_Monthly_Return'!Q18 -> 0.057280908 | J22: ='23''24''_Monthly_Return'!R18 -> -0.017988053 | K22: ='23''24''_Monthly_Return'!S18 -> 0.010611906
C23: Jun | D23: ='23''24''_Monthly_Return'!L19 -> -0.051724223 | E23: ='23''24''_Monthly_Return'!M19 -> -0.017949343 | F23: ='23''24''_Monthly_Return'!N19 -> -0.1146341 | G23: ='23''24''_Monthly_Return'!O19 -> -0.081597306 | H23: ='23''24''_Monthly_Return'!P19 -> 0.0074988994 | I23: ='23''24''_Monthly_Return'!Q19 -> -0.044386411 | J23: ='23''24''_Monthly_Return'!R19 -> 0.0080028173 | K23: ='23''24''_Monthly_Return'!S19 -> 0.013617622
C24: Jul | D24: ='23''24''_Monthly_Return'!L20 -> -0.017424144 | E24: ='23''24''_Monthly_Return'!M20 -> 0.029390201 | F24: ='23''24''_Monthly_Return'!N20 -> 0.024793338 | G24: ='23''24''_Monthly_Return'!O20 -> 0.037807218 | H24: ='23''24''_Monthly_Return'!P20 -> -0.015761818 | I24: ='23''24''_Monthly_Return'!Q20 -> 0.019808739 | J24: ='23''24''_Monthly_Return'!R20 -> 0.0021171128 | K24: ='23''24''_Monthly_Return'!S20 -> 0.00097114978
C25: Aug | D25: ='23''24''_Monthly_Return'!L21 -> 0.050886619 | E25: ='23''24''_Monthly_Return'!M21 -> -0.052872382 | F25: ='23''24''_Monthly_Return'!N21 -> 0.0040322501 | G25: ='23''24''_Monthly_Return'!O21 -> 0.0072859587 | H25: ='23''24''_Monthly_Return'!P21 -> 0.1040925 | I25: ='23''24''_Monthly_Return'!Q21 -> 0.016744839 | J25: ='23''24''_Monthly_Return'!R21 -> -0.055985865 | K25: ='23''24''_Monthly_Return'!S21 -> 0.073319261
C26: Sep | D26: ='23''24''_Monthly_Return'!L22 -> -0.092076379 | E26: ='23''24''_Monthly_Return'!M22 -> 0.003749736 | F26: ='23''24''_Monthly_Return'!N22 -> 0.021419076 | G26: ='23''24''_Monthly_Return'!O22 -> -0.20162747 | H26: ='23''24''_Monthly_Return'!P22 -> 0.062046752 | I26: ='23''24''_Monthly_Return'!Q22 -> -0.023056759 | J26: ='23''24''_Monthly_Return'!R22 -> -0.095486767 | K26: ='23''24''_Monthly_Return'!S22 -> -0.1270152
C27: Oct | D27: ='23''24''_Monthly_Return'!L23 -> 0.010195698 | E27: ='23''24''_Monthly_Return'!M23 -> 0.063508653 | F27: ='23''24''_Monthly_Return'!N23 -> -0.01703808 | G27: ='23''24''_Monthly_Return'!O23 -> -0.15383481 | H27: ='23''24''_Monthly_Return'!P23 -> 0.015553908 | I27: ='23''24''_Monthly_Return'!Q23 -> -0.17180783 | J27: ='23''24''_Monthly_Return'!R23 -> 0.063298971 | K27: ='23''24''_Monthly_Return'!S23 -> -0.047117728
C28: Nov | D28: ='23''24''_Monthly_Return'!L24 -> -0.018400028 | E28: ='23''24''_Monthly_Return'!M24 -> 0.029618234 | F28: ='23''24''_Monthly_Return'!N24 -> -0.027999945 | G28: ='23''24''_Monthly_Return'!O24 -> 0.038940629 | H28: ='23''24''_Monthly_Return'!P24 -> 0.043332052 | I28: ='23''24''_Monthly_Return'!Q24 -> 0.045602615 | J28: ='23''24''_Monthly_Return'!R24 -> -0.018227672 | K28: ='23''24''_Monthly_Return'!S24 -> -0.038942239
C29: Dev | D29: ='23''24''_Monthly_Return'!L25 -> -0.066829612 | E29: ='23''24''_Monthly_Return'!M25 -> 0.06687581 | F29: ='23''24''_Monthly_Return'!N25 -> 0 | G29: ='23''24''_Monthly_Return'!O25 -> 0.0025773196 | H29: ='23''24''_Monthly_Return'!P25 -> 0.021124329 | I29: ='23''24''_Monthly_Return'!Q25 -> -0.066978206 | J29: ='23''24''_Monthly_Return'!R25 -> -0.035354485 | K29: ='23''24''_Monthly_Return'!S25 -> -0.01922352
D31: CORRELATION MATRIX
B32: SD | C32: Company | D32: BA | E32: HSBA | F32: BNC | G32: KNOS | H32: RR | I32: JDW | J32: SHEL | K32: AZN
B33: {=TRANSPOSE(D1:K1)} -> 0.19634389 | C33: BA | D33: =CORREL($D$6:$D$29, D6:D29) -> 1 | E33: =CORREL($D$6:$D$29, E6:E29) -> -0.47561066 | F33: =CORREL($D$6:$D$29, F6:F29) -> 0.10767861 | G33: =CORREL($D$6:$D$29, G6:G29) -> 0.19775924 | H33: =CORREL($D$6:$D$29, H6:H29) -> 0.26053099 | I33: =CORREL($D$6:$D$29, I6:I29) -> 0.26936723 | J33: =CORREL($D$6:$D$29, J6:J29) -> 0.25574862 | K33: =CORREL($D$6:$D$29, K6:K29) -> 0.21807877
B34: 0.23418518 | C34: HSBA | D34: =CORREL($E$6:$E$29, D6:D29) -> -0.47561066 | E34: =CORREL($E$6:$E$29, E6:E29) -> 1 | F34: =CORREL($E$6:$E$29, F6:F29) -> 0.43741834 | G34: =CORREL($E$6:$E$29, G6:G29) -> 0.01509585 | H34: =CORREL($E$6:$E$29, H6:H29) -> -0.0065772368 | I34: =CORREL($E$6:$E$29, I6:I29) -> -0.23870601 | J34: =CORREL($E$6:$E$29, J6:J29) -> 0.49713101 | K34: =CORREL($E$6:$E$29, K6:K29) -> 0.16171303
B35: 0.26223325 | C35: BNC | D35: =CORREL($F$6:$F$29,D6:D29) -> 0.10767861 | E35: =CORREL($F$6:$F$29,E6:E29) -> 0.43741834 | F35: =CORREL($F$6:$F$29,F6:F29) -> 1 | G35: =CORREL($F$6:$F$29,G6:G29) -> -0.089143848 | H35: =CORREL($F$6:$F$29,H6:H29) -> 0.60979452 | I35: =CORREL($F$6:$F$29,I6:I29) -> 0.043292078 | J35: =CORREL($F$6:$F$29,J6:J29) -> 0.38533902 | K35: =CORREL($F$6:$F$29,K6:K29) -> 0.029067914
B36: 0.30992316 | C36: KNOS | D36: =CORREL($G$6:$G$29, D6:D29) -> 0.19775924 | E36: =CORREL($G$6:$G$29, E6:E29) -> 0.01509585 | F36: =CORREL($G$6:$G$29, F6:F29) -> -0.089143848 | G36: =CORREL($G$6:$G$29, G6:G29) -> 1 | H36: =CORREL($G$6:$G$29, H6:H29) -> -0.11639715 | I36: =CORREL($G$6:$G$29, I6:I29) -> 0.33451433 | J36: =CORREL($G$6:$G$29, J6:J29) -> -0.15698589 | K36: =CORREL($G$6:$G$29, K6:K29) -> 0.31121992
B37: 0.37282277 | C37: RR | D37: =CORREL($H$6:$H$29, D6:D29) -> 0.26053099 | E37: =CORREL($H$6:$H$29, E6:E29) -> -0.0065772368 | F37: =CORREL($H$6:$H$29, F6:F29) -> 0.60979452 | G37: =CORREL($H$6:$H$29, G6:G29) -> -0.11639715 | H37: =CORREL($H$6:$H$29, H6:H29) -> 1 | I37: =CORREL($H$6:$H$29, I6:I29) -> 0.37624748 | J37: =CORREL($H$6:$H$29, J6:J29) -> 0.14059524 | K37: =CORREL($H$6:$H$29, K6:K29) -> -0.051947132
B38: 0.35412736 | C38: JDW | D38: =CORREL($I$6:$I$29, D6:D29) -> 0.26936723 | E38: =CORREL($I$6:$I$29, E6:E29) -> -0.23870601 | F38: =CORREL($I$6:$I$29, F6:F29) -> 0.043292078 | G38: =CORREL($I$6:$I$29, G6:G29) -> 0.33451433 | H38: =CORREL($I$6:$I$29, H6:H29) -> 0.37624748 | I38: =CORREL($I$6:$I$29, I6:I29) -> 1 | J38: =CORREL($I$6:$I$29, J6:J29) -> -0.28589461 | K38: =CORREL($I$6:$I$29, K6:K29) -> 0.2949569
B39: 0.19010922 | C39: SHEL | D39: =CORREL($J$6:$J$29, D6:D29) -> 0.25574862 | E39: =CORREL($J$6:$J$29, E6:E29) -> 0.49713101 | F39: =CORREL($J$6:$J$29, F6:F29) -> 0.38533902 | G39: =CORREL($J$6:$J$29, G6:G29) -> -0.15698589 | H39: =CORREL($J$6:$J$29, H6:H29) -> 0.14059524 | I39: =CORREL($J$6:$J$29, I6:I29) -> -0.28589461 | J39: =CORREL($J$6:$J$29, J6:J29) -> 1 | K39: =CORREL($J$6:$J$29, K6:K29) -> 0.3517493
B40: 0.19158111 | C40: AZN | D40: =CORREL($K$6:$K$29, D6:D29) -> 0.21807877 | E40: =CORREL($K$6:$K$29, E6:E29) -> 0.16171303 | F40: =CORREL($K$6:$K$29, F6:F29) -> 0.029067914 | G40: =CORREL($K$6:$K$29, G6:G29) -> 0.31121992 | H40: =CORREL($K$6:$K$29, H6:H29) -> -0.051947132 | I40: =CORREL($K$6:$K$29, I6:I29) -> 0.2949569 | J40: =CORREL($K$6:$K$29, J6:J29) -> 0.3517493 | K40: =CORREL($K$6:$K$29, K6:K29) -> 1
D42: COVARIANCE MATRIX
...

Sheet 23' price
B1: Close
A2: Ticker | B2: AZN.L | C2: BA.L | D2: BNC.L | E2: HSBA.L | F2: JDW.L | G2: KNOS.L | H2: RR.L | I2: SHEL.L
A3: 44929 | B3: 11527.486 | C3: 861.66382 | D3: 251.0815 | E3: 529.04565 | F3: 452.4953 | G3: 1542.1426 | H3: 98.90181 | I3: 2365.1152
A4: 44930 | B4: 11595.447 | C4: 849.47137 | D4: 261.17471 | E4: 542.62378 | F4: 466.49207 | G4: 1548.1392 | H4: 101.3916 | I4: 2283.1802
A5: 44931 | B5: 11703.387 | C5: 847.07294 | D5: 262.12405 | E5: 564.38855 | F5: 473.09055 | G5: 1559.1329 | H5: 102.6515 | I5: 2309.6597
A6: 44932 | B6: 11775.347 | C6: 857.26654 | D6: 266.67105 | E6: 567.68329 | F6: 476.88965 | G6: 1556.1348 | H6: 102.89148 | I6: 2348.1289
A7: 44935 | B7: 11729.372 | C7: 834.6806 | D7: 265.72165 | E7: 562.29205 | F7: 481.88849 | G7: 1539.1442 | H7: 103.7514 | I7: 2377.106
A8: 44936 | B8: 11795.334 | C8: 838.87799 | D8: 272.71698 | E8: 563.19049 | F8: 485.48767 | G8: 1563.1309 | H8: 101.01163 | I8: 2374.6079
A9: 44937 | B9: 11627.43 | C9: 824.48694 | D9: 268.22 | E9: 568.6817 | F9: 483.08826 | G9: 1417.2119 | H9: 102.5715 | I9: 2404.0845
A10: 44938 | B10: 11441.535 | C10: 832.68188 | D10: 272.66699 | E10: 580.86206 | F10: 496.68509 | G10: 1467.1841 | H10: 103.99139 | I10: 2430.5632
A11: 44939 | B11: 11649.416 | C11: 832.2821 | D11: 276.51443 | E11: 590.24689 | F11: 490.08664 | G11: 1472.1813 | H11: 108.75099 | I11: 2438.5566
A12: 44942 | B12: 11669.405 | C12: 831.08282 | D12: 273.7663 | E12: 595.13898 | F12: 492.28607 | G12: 1474.1803 | H12: 107.15112 | I12: 2423.5686
A13: 44943 | B13: 11593.448 | C13: 837.87866 | D13: 274.06607 | E13: 590.24689 | F13: 471.49091 | G13: 1477.1786 | H13: 108.53101 | I13: 2417.074
A14: 44944 | B14: 11571.462 | C14: 836.87933 | D14: 273.51645 | E14: 589.74774 | F14: 473.2905 | G14: 1488.1725 | H14: 108.25103 | I14: 2401.5862
... A253: 45289 | B253: 10596.193 | C253: 1110.109 | D253: 328.84717 | E253: 634.90582 | F253: 810.3125 | G253: 1118.6268 | H253: 299.67517 | I253: 2570.4722

Sheet 24' price
A1: Price | B1: Close
A2: Ticker | B2: AZN.L | C2: BA.L | D2: BNC.L | E2: HSBA.L | F2: JDW.L | G2: KNOS.L | H2: RR.L | I2: SHEL.L
A3: 45293 | B3: 10784.126 | C3: 1115.6071 | D3: 332.35663 | E3: 629.89496 | F3: 804.3139 | G3: 1094.6348 | H3: 298.07532 | I3: 2574.9521
A4: 45294 | B4: 10736.144 | C4: 1133.6008 | D4: 326.35922 | E4: 624.79987 | F4: 807.81311 | G4: 1046.6508 | H4: 294.77557 | I4: 2592.4485
A5: 45295 | B5: 10860.099 | C5: 1155.0933 | D5: 331.85687 | E5: 631.89294 | F5: 815.31134 | G5: 1050.6494 | H5: 297.77533 | I5: 2593.9482
A6: 45296 | B6: 10754.137 | C6: 1152.5941 | D6: 333.85602 | E6: 633.69128 | F6: 807.31323 | G6: 1034.6548 | H6: 296.57544 | I6: 2570.4531
A7: 45297 | B7: 10768.132 | C7: 1144.5969 | D7: 335.35538 | E7: 639.3858 | F7: 814.81152 | G7: 1043.6519 | H7: 305.17471 | I7: 2490.47
A8: 45298 | B8: 10898.085 | C8: 1146.0963 | D8: 331.35709 | E8: 633.89117 | F8: 810.81244 | G8: 1021.6591 | H8: 308.77441 | I8: 2480.4724
A9: 45299 | B9: 10896.086 | C9: 1155.0933 | D9: 330.85727 | E9: 630.09479 | F9: 812.81195 | G9: 1039.6532 | H9: 309.17441 | I9: 2446.9792
A10: 45300 | B10: 10826.111 | C10: 1163.0905 | D10: 323.36053 | E10: 610.81329 | F10: 812.31207 | G10: 1016.6608 | H10: 296.9754 | I10: 2443.98
A11: 45301 | B11: 10858.101 | C11: 1189.0813 | D11: 327.85858 | E11: 609.51447 | F11: 827.80847 | G11: 1019.6598 | H11: 304.97473 | I11: 2460.4763
A12: 45302 | B12: 10848.103 | C12: 1177.5853 | D12: 326.35922 | E12: 595.8277 | F12: 827.80847 | G12: 992.16895 | H12: 299.97516 | I12: 2459.4768
A13: 45303 | B13: 10642.177 | C13: 1180.5844 | D13: 316.36356 | E13: 592.93048 | F13: 832.80731 | G13: 1003.6652 | H13: 298.17529 | I13: 2434.9819
A14: 45304 | B14: 10442.249 | C14: 1191.5803 | D14: 313.61472 | E14: 587.13605 | F14: 830.30786 | G14: 995.66785 | H14: 296.57544 | I14: 2377.9941
... A255: 45545 | B255: 10406.506 | C255: 1144.8646 | D255: 364.42657 | E255: 781.30414 | F255: 598.96332 | G255: 778 | H255: 570.35278 | I255: 2441.7437

Sheet 23'24'_Monthly_Return
A1: Ticker | B1: BA.L | C1: HSBA.L | D1: BNC.L | E1: KNOS.L | F1: RR.L | G1: JDW.L | H1: SHEL.L | I1: AZN.L | K1: Monthly Return | L1: BA.L | M1: HSBA.L | N1: BNC.L | O1: KNOS.L | P1: RR.L | Q1: JDW.L | R1: SHEL.L | S1: AZN.L
A2: 44926 | B2: 855.46771 | C2: 514.86859 | D2: 248.33333 | E2: 1542.1425 | F2: 93.192276 | G2: 444.09726 | H2: 2324.1479 | I2: 11211.664 | K2: Jan | L2: =(B3-B2)/B2 -> 0.00093450456 | M2: =(C3-C2)/C2 -> 0.15648643 | N2: =(D3-D2)/D2 -> 0.13682102 | O2: =(E3-E2)/E2 -> -0.045366225 | P2: =(F3-F2)/F2 -> 0.13454938 | Q2: =(G3-G2)/G2 -> 0.022512367 | R2: =(H3-H2)/H2 -> 0.020636343 | S2: =(I3-I2)/I2 -> -0.055981389
A3: 44957 | B3: 856.26715 | C3: 595.43854 | D3: 282.31055 | E3: 1472.1813 | F3: 105.73124 | G3: 454.09494 | H3: 2372.1099 | I3: 10584.02 | K3: Feb | L3: =(B4-B3)/B3 -> 0.048085901 | M3: =(C4-C3)/C3 -> 0.065727452 | N3: =(D4-D3)/D3 -> 0.15274326 | O3: =(E4-E3)/E3 -> -0.055668651 | P3: =(F4-F3)/F3 -> 0.37072066 | Q3: =(G4-G3)/G3 -> 0.23844118 | R3: =(H4-H3)/H3 -> 0.064337029 | S3: =(I4-I3)/I3 -> 0.027529803
A4: 44985 | B4: 897.44153 | C4: 634.5752 | D4: 325.43158 | E4: 1390.2269 | F4: 144.92799 | G4: 562.36987 | H4: 2524.7244 | I4: 10875.396 | K4: Mar | L4: =(B5-B4)/B4 -> 0.094209396 | M4: =(C5-C4)/C4 -> -0.1348973 | N4: =(D5-D4)/D4 -> -0.077844344 | O4: =(E5-E4)/E4 -> -0.006470251 | P4: =(F5-F4)/F4 -> 0.028149607 | Q4: =(G5-G4)/G4 -> 0.27111111 | R4: =(H5-H4)/H4 -> -0.086285429 | S4: =(I5-I4)/I4 -> 0.0323529
A5: 45016 | B5: 981.98895 | C5: 548.97272 | D5: 300.09857 | E5: 1381.2318 | F5: 149.00766 | G5: 714.83459 | H5: 2306.8774 | I5: 11227.246 | K5: Apr | L5: =(B6-B5)/B5 -> 0.032123935 | M5: =(C6-C5)/C5 -> 0.043842097 | N5: =(D6-D5)/D5 -> -0.062410626 | O5: =(E6-E5)/E5 -> -0.10274951 | P5: =(F6-F5)/F5 -> 0.021003821 | Q5: =(G6-G5)/G5 -> -0.002797167 | R5: =(H6-H5)/H5 -> 0.062161696 | S5: =(I6-I5)/I5 -> 0.045762175
A6: 45044 | B6: 1013.5343 | C6: 573.04083 | D6: 281.36923 | E6: 1239.3109 | F6: 152.13739 | G6: 712.83508 | H6: 2450.2769 | I6: 11741.029 | K6: May | L6: =(B7-B6)/B6 -> -0.084615349 | M6: =(C7-C6)/C6 -> 0.029240147 | N6: =(D7-D6)/D6 -> -0.071048005 | O6: =(E7-E6)/E6 -> 0.033870889 | P6: =(F7-F6)/F6 -> -0.05816623 | Q6: =(G7-G6)/G6 -> 0.028751726 | R6: =(H7-H6)/H6 -> -0.094325976 | S6: =(I7-I6)/I6 -> -0.0073216636
A7: 45077 | B7: 927.77374 | C7: 589.79663 | D7: 261.37851 | E7: 1281.2875 | F7: 143.28813 | G7: 733.33032 | H7: 2219.1521 | I7: 11655.065 | K7: Jun | L7: =(B8-B7)/B7 -> -0.0012928399 | M7: =(C8-C7)/C7 -> 0.052836692 | N7: =(D8-D7)/D7 -> 0.13575531 | O7: =(E8-E7)/E7 -> -0.039001527 | P7: =(F8-F7)/F7 -> 0.054082352 | Q7: =(G8-G7)/G7 -> -0.08316285 | R7: =(H8-H7)/H7 -> 0.054942618 | S7: =(I8-I7)/I7 -> -0.032933139
A8: 45107 | B8: 926.57428 | C8: 620.95953 | D8: 296.86203 | E8: 1231.3153 | F8: 151.03749 | G8: 672.34448 | H8: 2341.0781 | I8: 11271.228 | K8: Jul | L8: =(B9-B8)/B8 -> 0.0047465275 | M8: =(C9-C8)/C8 -> 0.039568889 | N8: =(D9-D8)/D8 -> 0.060606061 | O8: =(E9-E8)/E8 -> 0.0633117 | P8: =(F9-F8)/F8 -> 0.22376693 | Q8: =(G9-G8)/G8 -> 0.0052043939 | R8: =(H9-H8)/H8 -> 0.010031957 | S8: =(I9-I8)/I8 -> -0.0079815542
A9: 45138 | B9: 930.97229 | C9: 645.53021 | D9: 314.85367 | E9: 1309.272 | F9: 184.83469 | G9: 675.84363 | H9: 2364.5637 | I9: 11181.266 | K9: Aug | L9: =(B10-B9)/B9 -> 0.08170497 | M9: =(C10-C9)/C9 -> -0.097674277 | N9: =(D10-D9)/D9 -> -0.026984165 | O9: =(E10-E9)/E9 -> -0.072519038 | P9: =(F10-F9)/F9 -> 0.20259671 | Q9: =(G10-G9)/G9 -> 0.069526639 | R9: =(H10-H9)/H9 -> 0.019340434 | S9: =(I10-I9)/I9 -> -0.046783141
A10: 45169 | B10: 1007.0374 | C10: 582.47852 | D10: 306.3576 | E10: 1214.3248 | F10: 222.28159 | G10: 722.83276 | H10: 2410.2954 | I10: 10658.171 | K10: Sep | L10: =(B11-B10)/B10 -> -0.0096278024 | M10: =(C11-C10)/C10 -> 0.10598535 | N10: =(D11-D10)/D10 -> 0.01957589 | O10: =(E11-E10)/E10 -> -0.054189948 | P10: =(F11-F10)/F10 -> -0.0062978095 | Q10: =(G11-G10)/G10 -> -0.043568412 | R10: =(H11-H10)/H10 -> 0.08065529 | S10: =(I11-I10)/I10 -> 0.041268129
A11: 45198 | B11: 997.3418 | C11: 644.21271 | D11: 312.35483 | E11: 1148.5206 | F11: 220.8817 | G11: 691.34009 | H11: 2604.6985 | I11: 11098.014 | K11: Oct | L11: =(B12-B11)/B11 -> 0.10655277 | M11: =(C12-C11)/C11 -> -0.081563132 | N11: =(D12-D11)/D11 -> -0.036800103 | O11: =(E12-E11)/E11 -> -0.023498618 | P11: =(F12-F11)/F11 -> -0.024898204 | Q11: =(G12-G11)/G11 -> -0.086044869 | R11: =(H12-H11)/H11 -> 0.015541045 | S11: =(I12-I11)/I11 -> -0.076742952
A12: 45230 | B12: 1103.6113 | C12: 591.6687 | D12: 300.86014 | E12: 1121.532 | F12: 215.38214 | G12: 631.85382 | H12: 2645.1782 | I12: 10246.319 | K12: Nov | L12: =(B13-B12)/B12 -> -0.048913015 | M12: =(C13-C12)/C12 -> 0.016678736 | N12: =(D13-D12)/D12 -> 0.07475089 | O12: =(E13-E12)/E12 -> -0.13941104 | P12: =(F13-F12)/F12 -> 0.24791085 | Q12: =(G13-G12)/G12 -> 0.085443003 | R12: =(H13-H12)/H12 -> -0.032588132 | S12: =(I13-I12)/I12 -> -0.012097522
A13: 45260 | B13: 1049.6304 | C13: 601.53699 | D13: 323.3497 | E13: 965.17804 | F13: 268.77771 | G13: 685.84131 | H13: 2558.9768 | I13: 10122.364 | K13: Dec | L13: =(B14-B13)/B13 -> 0.057618986 | M13: =(C14-C13)/C13 -> 0.055472625 | N13: =(D14-D13)/D13 -> 0.017001615 | O13: =(E14-E13)/E13 -> 0.15898496 | P13: =(F14-F13)/F13 -> 0.11495544 | Q13: =(G14-G13)/G13 -> 0.18148687 | R13: =(H14-H13)/H13 -> 0.004492171 | S13: =(I14-I13)/I13 -> 0.046810122
... A25: 45625 | B25: 1226.8549 | C25: 732.32904 | D25: 364.42657 | E25: 776 | F25: 558.55371 | G25: 641.96069 | H25: 2531.2341 | I25: 10610.477 | K25: Dec | L25: =(B26-B25)/B25 -> -0.066829612 | M25: =(C26-C25)/C25 -> 0.06687581 | N25: =(D26-D25)/D25 -> 0 | O25: =(E26-E25)/E25 -> 0.0025773196 | P25: =(F26-F25)/F25 -> 0.021124329 | Q25: =(G26-G25)/G25 -> -0.066978206 | R25: =(H26-H25)/H25 -> -0.035354485 | S25: =(I26-I25)/I25 -> -0.01922352
A26: 45656 | B26: 1144.8646 | C26: 781.30414 | D26: 364.42657 | E26: 778 | F26: 570.35278 | G26: 598.96332 | H26: 2441.7437 | I26: 10406.506

Sheet Risk

Sheet Volumn
A1: Price | B1: Volume
A2: Ticker | B2: AZN.L | C2: BA.L | D2: BNC.L | E2: HSBA.L | F2: JDW.L | G2: KNOS.L | H2: RR.L | I2: SHEL.L
A3: Date
A4: 45293 | B4: 1688733 | C4: 4781214 | D4: 2944916 | E4: 39992864 | F4: 215379 | G4: 130998 | H4: 23479714 | I4: 8129974
A5: 45294 | B5: 2972338 | C5: 4973585 | D5: 4917806 | E5: 26407890 | F5: 154864 | G5: 139765 | H5: 45508725 | I5: 13649356
A6: 45295 | B6: 1896074 | C6: 6488481 | D6: 18081713 | E6: 26385924 | F6: 234639 | G6: 160676 | H6: 103963159 | I6: 11815892
A7: 45296 | B7: 1161094 | C7: 4282192 | D7: 8201768 | E7: 56358956 | F7: 151175 | G7: 107424 | H7: 29036198 | I7: 20044598
A8: 45299 | B8: 1921363 | C8: 4583019 | D8: 6141179 | E8: 21200929 | F8: 283016 | G8: 93569 | H8: 79642068 | I8: 23073449
A9: 45300 | B9: 3005457 | C9: 6917546 | D9: 8942298 | E9: 48042479 | F9: 290921 | G9: 203934 | H9: 20612899 | I9: 20183458
A10: 45301 | B10: 1411866 | C10: 5950265 | D10: 12161323 | E10: 19739089 | F10: 116548 | G10: 165063 | H10: 12525260 | I10: 14059415
